
예외처리는 에러를 해결하는 것이 아닌, 에러를 회피하는 방안 중 프로그래밍 언어에서 문법적으로 지원하는 하나의 기술이다. 에러는 크게 두 가지로 나눌 수 있는데, 오류와 Exception으로 나뉜다. 오류의 경우 회피할 수 없다. 하지만 Exception의 경우 회피가 어느정도 가능하다. 하지만 이 역시 처음부터 오류인 경우와, Runtime시 오류가 나는 상황으로 나눌 수 있다.



## 0. try ~ catch

```java

int[] arr1 = {1,2,3};

for(int i = 0; i<4; i++) {
	try{
		System.out.println(arr1[i]);
	}catch(Error Type e) {
		// ...logic of Exception Handling
	}
}

```

예외가 발생한다면 try 블럭을 벗어나 catch 블럭으로 진입하게 된다. try 블럭을 진행하다 Exception / 예외를 만날 경우 더 이상 아래 코드를 진행시키지 않고 catch 블록으로 넘어간다.

```java

try{
	System.out.println("hello");
	int su1 = 0;
	int su2 = 1;
	int su3 = su2/su1;
	System.out.println("hello2");
}catch(ErrorType e) {
	
}

System.out.println("Hello3");

```

try 블럭에서는 su3부터 에러가 발생하기 때문에 `hello2`를 출력시키는 코드는 실행시키지 않고 catch 블럭으로 이동한다. 그리고 다시 try로 돌아오지 않고 try-catch 블럭을 모두 빠져나간다.

try-catch는 얼마만큼 블럭을 지정하느냐에 따라 그 퍼포먼스가 다르다. 따라서 상황에 맞게 유연하게 블럭을 지정하는 것이 중요하다.


## 0-1. error 객체

catch 블럭에 작성하는 에러의 경우, 객체를 선언하는 것과 동일한 형태를 가지는 코드가 있다. `Error Type a` 는 에러객체를 나타내는 타입이다. 에러 종류에 따라 다양한 클래스가 존재한다. 대표적으로는 ArrayIndexOutOfBoundsException, ArithmeticException 등등이 있다.

JAVA의 error 객체는 java.lang.Object를 상속받고, 그 아래에는 또 다시 Error를 나타내는 객체를 상속한다. 이에 따라, 에러가 여러번 날 수 있는 상황에서는 다양한 에러들의 공통 부모를 찾아 catch 블럭에 작성해줄 수도 있다. 아래 코드를 보자.

```java

int[] arr = {1,2,0,4,5};

try {
	for(int i = 0; i<6; i++){
		try{
			System.out.println(i/arr[i]);
		}catch(ArithmeticException e){
			// ...logic of Exception	
		}
	}
}catch(ArrayIndexOutOfBoundsException e){
	// ...logic of Exception
}

```

위 코드는 두 가지 Exception 상황을 Handling하기 위해 try catch문을 썼다. 첫 번째로 일어날 수 있는 에러는, 0으로 나누는 에러, 그리고 두 번째는 배열의 길이를 벗어난 인덱스에 접근하였을 때다. 만약 여러가지 Exception 상황을 대비해야된다면 더 많은 try-catch문을 중첩하여 작성하여야 할 것이다. 아래 코드를 보자.

```java

try {
	for(int i = 0; i<6; i++) {
		System.out.println(i/arr[i]);
	}
}catch(RuntimeException e) {
	//  ...logic of Exception
}


```

ArrayIndexOutOfBoundsException과 ArithmeticException는 RuntimeException을 공통적으로 상속받는다. 그렇기 때문에 catch 블럭에서 RuntimeException으로 설정할 수 있다. 

catch 블럭은 연쇄적으로 작성할 수 있다. try를 한 번 작성하고, 에러가 여러번 발생했을 때를 감안하여 각 에러 객체를 연쇄적으로 작성할 수 있다.

```java

int[] arr = {1,2,3,0};

for(int i = 0; i<6; i++) {
	try {
		System.out.println(i/arr[i]);
	}catch(ArithmeticException e) {
		// ... logic of Exception
	}catch(ArrayIndexOutOfBoundsException e) {
		// ... logic of Exception
	}catch(RuntimeException e) {
		// ... logic of Exception
	}catch(Exception e) {
		// ... logic of Exception
	}	
}

```

여러 개의 에러가 발생할 수 있는 시나리오라면, 위와 같이 에러가 발생할 순서대로 catch 블럭을 작성할 수 있다. 위 코드를 예시를 들면, 가장 마지막에 있는 Exception 객체를 가장 첫 번째 catch 블럭에 올릴 경우, IDE에 따라서는 Dead Code라는 경고창이 뜨게 된다. ArithmeticException, ArrayIndexOutOfBoundsException, RuntimeException 에러 객체는 Exception 객체를 상속받는 자식 객체가 된다. 따라서 Exception 객체가 최상단 catch 블럭에 존재하면, 실제 ArrayIndexOutOfBoundsException 에러가 발생하였을 때, 정작 해당 에러 시 동작해야하는 예외처리코드는 동작하지 않게된다. 왜냐하면 Exception 에러 객체를 받는 catch 블럭에서 예외처리 코드가 실행되버리기 때문이다.

따라서 catch 블럭을 연쇄적으로 작성할 때에는 부모가 되는 에러 클래스를 아래로 작성하여야한다.